{"uuid": "7148824f-039e-4589-b960-7e07f1754a9f", "children": ["c1870896-4b72-43ce-8493-51cc3fb10101"], "befores": [{"name": "setup_function", "status": "broken", "statusDetails": {"message": "selenium.common.exceptions.WebDriverException: Message: An unknown server-side error occurred while processing the command. Original error: Could not find a connected Android device in 20338ms.\nStacktrace:\nUnknownError: An unknown server-side error occurred while processing the command. Original error: Could not find a connected Android device in 20338ms.\n    at getResponseForW3CError (C:\\Users\\piyus\\AppData\\Local\\Programs\\Appium Server GUI\\resources\\app\\node_modules\\appium\\node_modules\\appium-base-driver\\lib\\protocol\\errors.js:804:9)\n    at asyncHandler (C:\\Users\\piyus\\AppData\\Local\\Programs\\Appium Server GUI\\resources\\app\\node_modules\\appium\\node_modules\\appium-base-driver\\lib\\protocol\\protocol.js:380:37)\n", "trace": "  File \"C:\\Users\\piyus\\AppData\\Local\\Programs\\Python\\Python310\\lib\\site-packages\\pluggy\\callers.py\", line 187, in _multicall\n    res = hook_impl.function(*args)\n  File \"C:\\Users\\piyus\\AppData\\Local\\Programs\\Python\\Python310\\lib\\site-packages\\_pytest\\fixtures.py\", line 1130, in pytest_fixture_setup\n    result = call_fixture_func(fixturefunc, request, kwargs)\n  File \"C:\\Users\\piyus\\AppData\\Local\\Programs\\Python\\Python310\\lib\\site-packages\\_pytest\\fixtures.py\", line 902, in call_fixture_func\n    fixture_result = next(generator)\n  File \"C:\\Users\\piyus\\Desktop\\lp3thw\\Python Testing\\Appium Mobile Automation\\DummyProject\\TestCases\\conftest.py\", line 27, in setup_function\n    driver = webdriver.Remote(\"http://127.0.0.1:4723/wd/hub\", desired_caps)\n  File \"C:\\Users\\piyus\\AppData\\Local\\Programs\\Python\\Python310\\lib\\site-packages\\appium\\webdriver\\webdriver.py\", line 234, in __init__\n    super().__init__(\n  File \"C:\\Users\\piyus\\AppData\\Local\\Programs\\Python\\Python310\\lib\\site-packages\\selenium\\webdriver\\remote\\webdriver.py\", line 286, in __init__\n    self.start_session(capabilities, browser_profile)\n  File \"C:\\Users\\piyus\\AppData\\Local\\Programs\\Python\\Python310\\lib\\site-packages\\appium\\webdriver\\webdriver.py\", line 324, in start_session\n    response = self.execute(RemoteCommand.NEW_SESSION, w3c_caps)\n  File \"C:\\Users\\piyus\\AppData\\Local\\Programs\\Python\\Python310\\lib\\site-packages\\selenium\\webdriver\\remote\\webdriver.py\", line 440, in execute\n    self.error_handler.check_response(response)\n  File \"C:\\Users\\piyus\\AppData\\Local\\Programs\\Python\\Python310\\lib\\site-packages\\selenium\\webdriver\\remote\\errorhandler.py\", line 245, in check_response\n    raise exception_class(message, screen, stacktrace)\n"}, "start": 1683644200761, "stop": 1683644221223}], "start": 1683644200761, "stop": 1683644221372}